Traceback (most recent call last):
  File "/Users/cburr/opt/anaconda3/envs/turing-commons/lib/python3.9/site-packages/jupyter_cache/executors/utils.py", line 51, in single_nb_execution
    executenb(
  File "/Users/cburr/opt/anaconda3/envs/turing-commons/lib/python3.9/site-packages/nbclient/client.py", line 1117, in execute
    return NotebookClient(nb=nb, resources=resources, km=km, **kwargs).execute()
  File "/Users/cburr/opt/anaconda3/envs/turing-commons/lib/python3.9/site-packages/nbclient/util.py", line 78, in wrapped
    return just_run(coro(*args, **kwargs))
  File "/Users/cburr/opt/anaconda3/envs/turing-commons/lib/python3.9/site-packages/nbclient/util.py", line 57, in just_run
    return loop.run_until_complete(coro)
  File "/Users/cburr/opt/anaconda3/envs/turing-commons/lib/python3.9/asyncio/base_events.py", line 642, in run_until_complete
    return future.result()
  File "/Users/cburr/opt/anaconda3/envs/turing-commons/lib/python3.9/site-packages/nbclient/client.py", line 558, in async_execute
    await self.async_execute_cell(
  File "/Users/cburr/opt/anaconda3/envs/turing-commons/lib/python3.9/site-packages/nbclient/client.py", line 862, in async_execute_cell
    self._check_raise_for_error(cell, exec_reply)
  File "/Users/cburr/opt/anaconda3/envs/turing-commons/lib/python3.9/site-packages/nbclient/client.py", line 765, in _check_raise_for_error
    raise CellExecutionError.from_cell_and_msg(cell, exec_reply_content)
nbclient.exceptions.CellExecutionError: An error occurred while executing the following cell:
------------------
import random
import datetime
import uuid
import pandas as pd
import matplotlib.pyplot as plt
%matplotlib inline
------------------

[0;31m---------------------------------------------------------------------------[0m
[0;31mModuleNotFoundError[0m                       Traceback (most recent call last)
[0;32m/var/folders/_l/l9rdg7gs4kx5gglxn_1y0wn00000gq/T/ipykernel_60719/2101736591.py[0m in [0;36m<module>[0;34m[0m
[1;32m      2[0m [0;32mimport[0m [0mdatetime[0m[0;34m[0m[0;34m[0m[0m
[1;32m      3[0m [0;32mimport[0m [0muuid[0m[0;34m[0m[0;34m[0m[0m
[0;32m----> 4[0;31m [0;32mimport[0m [0mpandas[0m [0;32mas[0m [0mpd[0m[0;34m[0m[0;34m[0m[0m
[0m[1;32m      5[0m [0;32mimport[0m [0mmatplotlib[0m[0;34m.[0m[0mpyplot[0m [0;32mas[0m [0mplt[0m[0;34m[0m[0;34m[0m[0m
[1;32m      6[0m [0mget_ipython[0m[0;34m([0m[0;34m)[0m[0;34m.[0m[0mrun_line_magic[0m[0;34m([0m[0;34m'matplotlib'[0m[0;34m,[0m [0;34m'inline'[0m[0;34m)[0m[0;34m[0m[0;34m[0m[0m

[0;31mModuleNotFoundError[0m: No module named 'pandas'
ModuleNotFoundError: No module named 'pandas'

